Workbook
Name aa: Sheet1!$AH$2:$AP$2

Sheet Sheet1
A1: 1. Get the Distributor_Name & Status from Active List using Vlookup | E1: 2. Get mentined details by using Hlookup thru SMS ID | K1: 3. Get the SMSID & Name from Active List(without using vlookup & hlookup) | O1: 4. Find the count of Status As per given table Dynamic | S1: 5. Separate the STB and VC as per given below table and also put the 0 before the VC No | W1: 6. Replace the New Delhi with blank from below table | Z1: 7.Join all the rows in one Cell without using concatenate | AE1: 8. Remove number 1,2,3 and parenthesis (only alphabets should be left) | AH1: 9. Arrange and paste all VC's from row to column using function only | AR1: 10. Convert in TEXT formate | AW1: 11. Count number of "a" in below Cell | BB1: 12. Separate given below table on the basis of used delimiter("|") using formula OR without formula
A2: STB | B2: Distributor_Name | C2: Status | E2: SMSID | F2: Name | G2: STB | H2: VC | K2: STB | L2: SMSID | M2: Name | O2: Distributor_Name | P2: Count of Status 1 | Q2: Count of Status 2 | S2: STB & VC | T2: STB | U2: VC | W2: Address | X2: Address | Z2: Marketing | AA2: 325 | AB2: Communication | AC2: Marketing 325 Communication | AE2: anil13 cab12le id() | AF2: anilcable id | AH2: 1760105267 | AI2: 1760347043 | AJ2: 1760420917 | AK2: 1753366575 | AL2: 1760344903 | AM2: 1760347846 | AN2: 1760134838 | AO2: 1760203666 | AP2: 1760597792 | AR2: 7783274 | AS2: =FIXED(AR2) -> 7,783,274.00 | BB2: SMSID
A3: 06H9BAR42LT00028 | B3: {=VLOOKUP(A3,'Active List'!C:I,{6,7},0)} -> M D Cable(DEL711) | C3: 1 | E3: 83222 | F3: {=HLOOKUP(E3,TRANSPOSE('Active List'!$A:$D),2,0)} -> BHAGAT DARSHAN SINGH | G3: {=HLOOKUP(F3,TRANSPOSE('Active List'!$A:$B),{2,3,4},0)} -> #N/A | H3: {=HLOOKUP(G3,TRANSPOSE('Active List'!$A:$B),{2,3,4},0)} -> #N/A | K3: 06H9BAR42LT00028 | L3: =INDEX('Active List'!A:A,MATCH(Sheet1!K3,'Active List'!C:C,0)) -> 83222 | O3: M D Cable(DEL711) | P3: =COUNTIFS('Active List'!H:H,Sheet1!O3,'Active List'!I:I,1) -> 6 | Q3: =COUNTIFS('Active List'!H:H,Sheet1!O3,'Active List'!I:I,2) -> 2 | S3: 06H9BAR42LT00028 1760105267 | T3: =LEFT(S3,FIND(" ",S3)-1) -> 06H9BAR42LT00028 | U3: =CONCATENATE(0,RIGHT(S3,LEN(S3)-FIND(" ",S3))) -> 0 1760105267 | W3: 476, TYPEIV LAXMI BAI NAGARNew Delhi - 110023 DELHI New Delhi(INDIA) | X3: =SUBSTITUTE(W3,"New Delhi","") -> 476, TYPEIV LAXMI BAI NAGAR - 110023 DELHI (INDIA) | Z3: Communication | AA3: Marketing | AB3: 325 | AC3: =Z3&" "&AA3&" "&AB3 -> Communication Marketing 325 | AE3: a2nil1cabl3e id() | AF3: =SUBSTITUTE(SUBSTITUTE(SUBSTITUTE(SUBSTITUTE(SUBSTITUTE(SUBSTITUTE(SUBSTITUTE(SUBSTITUTE(SUBSTITUTE(SUBSTITUTE(SUBSTITUTE(SUBSTITUTE(AE3,"1",""),"2",""),"3",""),"4",""),"5",""),"6",""),"7",""),"8",""),"9",""),"0",""),"(",""),")","") -> anilcable id | AR3: 7800364 | AS3: =FIXED(AR3) -> 7,800,364.00 | AW3: aaaaabceaeaacdfik | AY3: =LEN(AW3)-LEN(SUBSTITUTE(AW3,"a","")) -> 8 | BB3: 83222|06H9BAR42LT00028|1760105267|3159|M D Cable(711001)|330|M D Cable(DEL711) | BD3: =LEN(AW3)-LEN(SUBSTITUTE(AW3,"a","")) -> 8
A4: 06H9BAR42LT00200 | B4: {=VLOOKUP(A4,'Active List'!C:I,{6,7},0)} -> Macwell Marketing Co Pvt Ltd (South Delhi Comm) | C4: 1 | E4: 83340 | F4: {=HLOOKUP(E4,TRANSPOSE('Active List'!$A:$B),2,0)} -> Sat Pal | K4: 06H9BAR42LT00200 | L4: =INDEX('Active List'!A:A,MATCH(Sheet1!K4,'Active List'!C:C,0)) -> 83340 | O4: Macwell Marketing Co Pvt Ltd (South Delhi Comm) | P4: =COUNTIFS('Active List'!H:H,Sheet1!O4,'Active List'!I:I,1) -> 9 | Q4: =COUNTIFS('Active List'!H:H,Sheet1!O4,'Active List'!I:I,2) -> 3 | S4: 06H9BAR42LT00200 1760347043 | T4: =LEFT(S4,FIND(" ",S4)-1) -> 06H9BAR42LT00200 | U4: =CONCATENATE(0,RIGHT(S4,LEN(S4)-FIND(" ",S4))) -> 0 1760347043 | W4: 96/FF HUMAYUN PUR,New Delhi - 110029 DELHI New Delhi(INDIA) | X4: =SUBSTITUTE(W4,"New Delhi","") -> 96/FF HUMAYUN PUR, - 110029 DELHI (INDIA) | Z4: 325 | AA4: Communication | AB4: Marketing | AC4: =Z4&" "&AA4&" "&AB4 -> 325 Communication Marketing | AE4: ashish32cab1232le id | AF4: =SUBSTITUTE(SUBSTITUTE(SUBSTITUTE(SUBSTITUTE(SUBSTITUTE(SUBSTITUTE(SUBSTITUTE(SUBSTITUTE(SUBSTITUTE(SUBSTITUTE(SUBSTITUTE(SUBSTITUTE(AE4,"1",""),"2",""),"3",""),"4",""),"5",""),"6",""),"7",""),"8",""),"9",""),"0",""),"(",""),")","") -> ashishcable id | AH4: {=TRANSPOSE(AH2)} -> 1760105267 | AR4: 7910269 | AS4: =FIXED(AR4) -> 7,910,269.00 | BB4: 83340|06H9BAR42LT00200|1760347043|3146|Om Shree Balalji Media Communication(708017)|325|Macwell Marketing Co Pvt Ltd (South Delhi Comm)
A5: 2213ICA2-1036259 | B5: {=VLOOKUP(A5,'Active List'!C:I,{6,7},0)} -> S.K Cable Network(DEL705) | C5: 1 | E5: 83540 | F5: {=HLOOKUP(E5,TRANSPOSE('Active List'!$A:$B),2,0)} -> PRASHANT | K5: 2213ICA2-1036259 | L5: =INDEX('Active List'!A:A,MATCH(Sheet1!K5,'Active List'!C:C,0)) -> 83540 | O5: S.K Cable Network(DEL705) | P5: =COUNTIFS('Active List'!H:H,Sheet1!O5,'Active List'!I:I,1) -> 2 | Q5: =COUNTIFS('Active List'!H:H,Sheet1!O5,'Active List'!I:I,2) -> 1 | S5: 2213ICA2-1036259 1760420917 | T5: =LEFT(S5,FIND(" ",S5)-1) -> 2213ICA2-1036259 | U5: =CONCATENATE(0,RIGHT(S5,LEN(S5)-FIND(" ",S5))) -> 0 1760420917 | W5: J4/71 GFLS KHIRKI EXTNNew Delhi - 110017 DELHI New Delhi(INDIA) | X5: =SUBSTITUTE(W5,"New Delhi","") -> J4/71 GFLS KHIRKI EXTN - 110017 DELHI (INDIA) | AE5: ashish12ca32ble id | AF5: =SUBSTITUTE(SUBSTITUTE(SUBSTITUTE(SUBSTITUTE(SUBSTITUTE(SUBSTITUTE(SUBSTITUTE(SUBSTITUTE(SUBSTITUTE(SUBSTITUTE(SUBSTITUTE(SUBSTITUTE(AE5,"1",""),"2",""),"3",""),"4",""),"5",""),"6",""),"7",""),"8",""),"9",""),"0",""),"(",""),")","") -> ashishcable id | AH5: 1760105267 | AR5: 7914942 | AS5: =FIXED(AR5) -> 7,914,942.00 | BB5: 83540|2213ICA2-1036259|1760420917|3155|Classic Vision(710002)|324|S.K Cable Network(DEL705)
A6: 06J8BAR49SM11680 | B6: {=VLOOKUP(A6,'Active List'!C:I,{6,7},0)} -> Macwell Marketing Co Pvt Ltd (South Delhi Comm) | C6: 1 | E6: 83541 | F6: {=HLOOKUP(E6,TRANSPOSE('Active List'!$A:$B),2,0)} -> SGT SP Yadav | K6: 06J8BAR49SM11680 | L6: =INDEX('Active List'!A:A,MATCH(Sheet1!K6,'Active List'!C:C,0)) -> 83541 | O6: Satellite Channels P. Ltd(DEL701) | P6: =COUNTIFS('Active List'!H:H,Sheet1!O6,'Active List'!I:I,1) -> 15 | Q6: =COUNTIFS('Active List'!H:H,Sheet1!O6,'Active List'!I:I,2) -> 5 | S6: 06J8BAR49SM11680 1760465717 | T6: =LEFT(S6,FIND(" ",S6)-1) -> 06J8BAR49SM11680 | U6: =CONCATENATE(0,RIGHT(S6,LEN(S6)-FIND(" ",S6))) -> 0 1760465717 | W6: 19 C/1 NWC, AIR FORCE STATION RACE COURSENew DelhiNew Delhi - 110003 DELHI New Delhi(INDIA) | X6: =SUBSTITUTE(W6,"New Delhi","") -> 19 C/1 NWC, AIR FORCE STATION RACE COURSE - 110003 DELHI (INDIA) | AE6: ashish ()cable id() | AF6: =SUBSTITUTE(SUBSTITUTE(SUBSTITUTE(SUBSTITUTE(SUBSTITUTE(SUBSTITUTE(SUBSTITUTE(SUBSTITUTE(SUBSTITUTE(SUBSTITUTE(SUBSTITUTE(SUBSTITUTE(AE6,"1",""),"2",""),"3",""),"4",""),"5",""),"6",""),"7",""),"8",""),"9",""),"0",""),"(",""),")","") -> ashish cable id | AH6: 1760105267 | AR6: 7973154 | AS6: =FIXED(AR6) -> 7,973,154.00 | BB6: 83541|06J8BAR49SM11680|1760465717|2887|Air Force Cable TV Network(700017)|325|Macwell Marketing Co Pvt Ltd (South Delhi Comm)
A7: 06J8BAR49SM32573 | B7: {=VLOOKUP(A7,'Active List'!C:I,{6,7},0)} -> S.K Cable Network(DEL705) | C7: 2 | E7: 83764 | F7: {=HLOOKUP(E7,TRANSPOSE('Active List'!$A:$B),2,0)} -> AKHILESH MISHRA | K7: 06J8BAR49SM32573 | L7: =INDEX('Active List'!A:A,MATCH(Sheet1!K7,'Active List'!C:C,0)) -> 83764 | O7: S.S Communications(DEL702) | P7: =COUNTIFS('Active List'!H:H,Sheet1!O7,'Active List'!I:I,1) -> 0 | Q7: =COUNTIFS('Active List'!H:H,Sheet1!O7,'Active List'!I:I,2) -> 1 | S7: 06J8BAR49SM32573 1760344903 | T7: =LEFT(S7,FIND(" ",S7)-1) -> 06J8BAR49SM32573 | U7: =CONCATENATE(0,RIGHT(S7,LEN(S7)-FIND(" ",S7))) -> 0 1760344903 | W7: H16/271 SANGAM VIHAR | X7: =SUBSTITUTE(W7,"New Delhi","") -> H16/271 SANGAM VIHAR | AE7: as12hish321cable id | AF7: =SUBSTITUTE(SUBSTITUTE(SUBSTITUTE(SUBSTITUTE(SUBSTITUTE(SUBSTITUTE(SUBSTITUTE(SUBSTITUTE(SUBSTITUTE(SUBSTITUTE(SUBSTITUTE(SUBSTITUTE(AE7,"1",""),"2",""),"3",""),"4",""),"5",""),"6",""),"7",""),"8",""),"9",""),"0",""),"(",""),")","") -> ashishcable id | AH7: 1760105267 | AR7: 7973194 | AS7: =FIXED(AR7) -> 7,973,194.00 | BB7: 83764|06J8BAR49SM32573|1760344903|3149|Mini Cable Darshan(709002)|324|S.K Cable Network(DEL705)
A8: 06J8BAR49SM32647 | B8: {=VLOOKUP(A8,'Active List'!C:I,{6,7},0)} -> Satellite Channels P. Ltd(DEL701) | C8: 1 | E8: 83811 | F8: {=HLOOKUP(E8,TRANSPOSE('Active List'!$A:$B),2,0)} -> G. S. BAIDI | K8: 06J8BAR49SM32647 | L8: =INDEX('Active List'!A:A,MATCH(Sheet1!K8,'Active List'!C:C,0)) -> 83811 | S8: 06J8BAR49SM32647 1760347846 | T8: =LEFT(S8,FIND(" ",S8)-1) -> 06J8BAR49SM32647 | U8: =CONCATENATE(0,RIGHT(S8,LEN(S8)-FIND(" ",S8))) -> 0 1760347846 | W8: L 31 S FLR LAJPAT NGR II | X8: =SUBSTITUTE(W8,"New Delhi","") -> L 31 S FLR LAJPAT NGR II | AE8: ashish2cab23le id() | AF8: =SUBSTITUTE(SUBSTITUTE(SUBSTITUTE(SUBSTITUTE(SUBSTITUTE(SUBSTITUTE(SUBSTITUTE(SUBSTITUTE(SUBSTITUTE(SUBSTITUTE(SUBSTITUTE(SUBSTITUTE(AE8,"1",""),"2",""),"3",""),"4",""),"5",""),"6",""),"7",""),"8",""),"9",""),"0",""),"(",""),")","") -> ashishcable id | AH8: 1760105267 | AR8: 8080654 | AS8: =FIXED(AR8) -> 8,080,654.00 | BB8: 83811|06J8BAR49SM32647|1760347846|4757|Satellite Channels P Ltd|320|Satellite Channels P. Ltd(DEL701)
A9: 0718BAU02DS10867 | B9: {=VLOOKUP(A9,'Active List'!C:I,{6,7},0)} -> Macwell Marketing Co Pvt Ltd (South Delhi Comm) | C9: 2 | E9: 84077 | F9: {=HLOOKUP(E9,TRANSPOSE('Active List'!$A:$B),2,0)} -> SANJAY KUMAR | K9: 0718BAU02DS10867 | L9: =INDEX('Active List'!A:A,MATCH(Sheet1!K9,'Active List'!C:C,0)) -> 84077 | S9: 0718BAU02DS10867 1760447627 | T9: =LEFT(S9,FIND(" ",S9)-1) -> 0718BAU02DS10867 | U9: =CONCATENATE(0,RIGHT(S9,LEN(S9)-FIND(" ",S9))) -> 0 1760447627 | W9: H.N0.3 F.F.ARJUN NGR.New Delhi - 110016 DELHI New Delhi-INDIA | X9: =SUBSTITUTE(W9,"New Delhi","") -> H.N0.3 F.F.ARJUN NGR. - 110016 DELHI -INDIA | AE9: ashish23ca1112ble id | AF9: =SUBSTITUTE(SUBSTITUTE(SUBSTITUTE(SUBSTITUTE(SUBSTITUTE(SUBSTITUTE(SUBSTITUTE(SUBSTITUTE(SUBSTITUTE(SUBSTITUTE(SUBSTITUTE(SUBSTITUTE(AE9,"1",""),"2",""),"3",""),"4",""),"5",""),"6",""),"7",""),"8",""),"9",""),"0",""),"(",""),")","") -> ashishcable id | AH9: 1760105267 | AR9: 8472454 | AS9: =FIXED(AR9) -> 8,472,454.00 | BB9: 84077|0718BAU02DS10867|1760447627|2876|Citi Communication(700006)|325|Macwell Marketing Co Pvt Ltd (South Delhi Comm)
A10: 2213ICA2-1033156 | B10: {=VLOOKUP(A10,'Active List'!C:I,{6,7},0)} -> S.K Cable Network(DEL705) | C10: 1 | E10: 84131 | F10: {=HLOOKUP(E10,TRANSPOSE('Active List'!$A:$B),2,0)} -> RAGHVENDRA | K10: 2213ICA2-1033156 | L10: =INDEX('Active List'!A:A,MATCH(Sheet1!K10,'Active List'!C:C,0)) -> 84131 | S10: 2213ICA2-1033156 1761333827 | T10: =LEFT(S10,FIND(" ",S10)-1) -> 2213ICA2-1033156 | U10: =CONCATENATE(0,RIGHT(S10,LEN(S10)-FIND(" ",S10))) -> 0 1761333827 | W10: FLAT NO. 96/5 SEC-1 PUSHP VIHAR | X10: =SUBSTITUTE(W10,"New Delhi","") -> FLAT NO. 96/5 SEC-1 PUSHP VIHAR | AE10: ashish13c321able id() | AF10: =SUBSTITUTE(SUBSTITUTE(SUBSTITUTE(SUBSTITUTE(SUBSTITUTE(SUBSTITUTE(SUBSTITUTE(SUBSTITUTE(SUBSTITUTE(SUBSTITUTE(SUBSTITUTE(SUBSTITUTE(AE10,"1",""),"2",""),"3",""),"4",""),"5",""),"6",""),"7",""),"8",""),"9",""),"0",""),"(",""),")","") -> ashishcable id | AH10: 1760105267 | AR10: 8863594 | AS10: =FIXED(AR10) -> 8,863,594.00 | BB10: 84131|2213ICA2-1033156|1761333827|4300|Sky Net Cable Network(705029)|324|S.K Cable Network(DEL705)
A11: 06j8bar49sm27232 | B11: {=VLOOKUP(A11,'Active List'!C:I,{6,7},0)} -> Satellite Channels P. Ltd(DEL701) | C11: 1 | E11: 84259 | F11: {=HLOOKUP(E11,TRANSPOSE('Active List'!$A:$B),2,0)} -> SUDARSHAN SACHDEV | K11: 06j8bar49sm27232 | L11: =INDEX('Active List'!A:A,MATCH(Sheet1!K11,'Active List'!C:C,0)) -> 84259 | S11: 06j8bar49sm27232 1760134838 | T11: =LEFT(S11,FIND(" ",S11)-1) -> 06j8bar49sm27232 | U11: =CONCATENATE(0,RIGHT(S11,LEN(S11)-FIND(" ",S11))) -> 0 1760134838 | W11: 3/1 IIIRD FLOOR JANGPURA EXTNNew Delhi - 110014 DELHI New Delhi(INDIA) | X11: =SUBSTITUTE(W11,"New Delhi","") -> 3/1 IIIRD FLOOR JANGPURA EXTN - 110014 DELHI (INDIA) | AE11: ashish321ca23ble id | AF11: =SUBSTITUTE(SUBSTITUTE(SUBSTITUTE(SUBSTITUTE(SUBSTITUTE(SUBSTITUTE(SUBSTITUTE(SUBSTITUTE(SUBSTITUTE(SUBSTITUTE(SUBSTITUTE(SUBSTITUTE(AE11,"1",""),"2",""),"3",""),"4",""),"5",""),"6",""),"7",""),"8",""),"9",""),"0",""),"(",""),")","") -> ashishcable id | AH11: 1760105267 | AR11: 7783274 | AS11: =FIXED(AR11) -> 7,783,274.00 | BB11: 84259|06j8bar49sm27232|1760134838|2933|Channi Cable Waves(701033)|320|Satellite Channels P. Ltd(DEL701)
A12: 0773BAU27DS27547 | B12: {=VLOOKUP(A12,'Active List'!C:I,{6,7},0)} -> M D Cable(DEL711) | C12: 1 | K12: 0773BAU27DS27547 | L12: =INDEX('Active List'!A:A,MATCH(Sheet1!K12,'Active List'!C:C,0)) -> 84389 | S12: 0773BAU27DS27547 1760203666 | T12: =LEFT(S12,FIND(" ",S12)-1) -> 0773BAU27DS27547 | U12: =CONCATENATE(0,RIGHT(S12,LEN(S12)-FIND(" ",S12))) -> 0 1760203666 | W12: DII/52 WEST KIDWAI NAGARNew Delhi - 110023 DELHI New Delhi(INDIA) | X12: =SUBSTITUTE(W12,"New Delhi","") -> DII/52 WEST KIDWAI NAGAR - 110023 DELHI (INDIA) | AE12: ashi123sh cab123le id() | AF12: =SUBSTITUTE(SUBSTITUTE(SUBSTITUTE(SUBSTITUTE(SUBSTITUTE(SUBSTITUTE(SUBSTITUTE(SUBSTITUTE(SUBSTITUTE(SUBSTITUTE(SUBSTITUTE(SUBSTITUTE(AE12,"1",""),"2",""),"3",""),"4",""),"5",""),"6",""),"7",""),"8",""),"9",""),"0",""),"(",""),")","") -> ashish cable id | AH12: 1760105267 | AR12: 7800364 | AS12: =FIXED(AR12) -> 7,800,364.00 | BB12: 84389|0773BAU27DS27547|1760203666|3159|M D Cable(711001)|330|M D Cable(DEL711)
A13: 2213ICA2-1033581 | B13: {=VLOOKUP(A13,'Active List'!C:I,{6,7},0)} -> M D Cable(DEL711) | C13: 1 | K13: 2213ICA2-1033581 | L13: =INDEX('Active List'!A:A,MATCH(Sheet1!K13,'Active List'!C:C,0)) -> 84390 | S13: 2213ICA2-1033581 1760597792 | T13: =LEFT(S13,FIND(" ",S13)-1) -> 2213ICA2-1033581 | U13: =CONCATENATE(0,RIGHT(S13,LEN(S13)-FIND(" ",S13))) -> 0 1760597792 | W13: C3 TYPEIII WEST KIDWAI NAGARNew Delhi - 110023 DELHI New Delhi(INDIA) | X13: =SUBSTITUTE(W13,"New Delhi","") -> C3 TYPEIII WEST KIDWAI NAGAR - 110023 DELHI (INDIA) | AR13: 7910269 | AS13: =FIXED(AR13) -> 7,910,269.00 | BB13: 84390|2213ICA2-1033581|1760597792|3159|M D Cable(711001)|330|M D Cable(DEL711)
A14: 06J8BAR49SM33494 | B14: {=VLOOKUP(A14,'Active List'!C:I,{6,7},0)} -> M D Cable(DEL711) | C14: 1 | K14: 06J8BAR49SM33494 | L14: =INDEX('Active List'!A:A,MATCH(Sheet1!K14,'Active List'!C:C,0)) -> 84392 | S14: 06J8BAR49SM33494 1760344576 | T14: =LEFT(S14,FIND(" ",S14)-1) -> 06J8BAR49SM33494 | U14: =CONCATENATE(0,RIGHT(S14,LEN(S14)-FIND(" ",S14))) -> 0 1760344576 | W14: 288,LAXMI BAI NAGARNew Delhi - 110023 DELHI New Delhi(INDIA) | X14: =SUBSTITUTE(W14,"New Delhi","") -> 288,LAXMI BAI NAGAR - 110023 DELHI (INDIA) | AR14: 7914942 | AS14: =FIXED(AR14) -> 7,914,942.00 | BB14: 84392|06J8BAR49SM33494|1760344576|3159|M D Cable(711001)|330|M D Cable(DEL711)
A15: 0708BAU03SM31087 | B15: {=VLOOKUP(A15,'Active List'!C:I,{6,7},0)} -> M D Cable(DEL711) | C15: 1 | K15: 0708BAU03SM31087 | L15: =INDEX('Active List'!A:A,MATCH(Sheet1!K15,'Active List'!C:C,0)) -> 84393 | S15: 0708BAU03SM31087 1760421982 | T15: =LEFT(S15,FIND(" ",S15)-1) -> 0708BAU03SM31087 | U15: =CONCATENATE(0,RIGHT(S15,LEN(S15)-FIND(" ",S15))) -> 0 1760421982 | W15: 345LAXMI BAI NAGARNew Delhi - 110023 DELHI New Delhi(INDIA) | X15: =SUBSTITUTE(W15,"New Delhi","") -> 345LAXMI BAI NAGAR - 110023 DELHI (INDIA) | AR15: 7973154 | AS15: =FIXED(AR15) -> 7,973,154.00 | BB15: 84393|0708BAU03SM31087|1760421982|3159|M D Cable(711001)|330|M D Cable(DEL711)
A16: 2213ICA2-1022226 | B16: {=VLOOKUP(A16,'Active List'!C:I,{6,7},0)} -> Satellite Channels P. Ltd(DEL701) | C16: 1 | K16: 2213ICA2-1022226 | L16: =INDEX('Active List'!A:A,MATCH(Sheet1!K16,'Active List'!C:C,0)) -> 84721 | S16: 2213ICA2-1022226 1760570248 | T16: =LEFT(S16,FIND(" ",S16)-1) -> 2213ICA2-1022226 | U16: =CONCATENATE(0,RIGHT(S16,LEN(S16)-FIND(" ",S16))) -> 0 1760570248 | W16: Q20BIST FLOOR | X16: =SUBSTITUTE(W16,"New Delhi","") -> Q20BIST FLOOR | AR16: 7973194 | AS16: =FIXED(AR16) -> 7,973,194.00 | BB16: 84721|2213ICA2-1022226|1760570248|2924|SIMRAN ENTERPRISES(701024)|320|Satellite Channels P. Ltd(DEL701)
A17: 2213iCA2-1123223 | B17: {=VLOOKUP(A17,'Active List'!C:I,{6,7},0)} -> Satellite Channels P. Ltd(DEL701) | C17: 2 | K17: 2213iCA2-1123223 | L17: =INDEX('Active List'!A:A,MATCH(Sheet1!K17,'Active List'!C:C,0)) -> 84743 | S17: 2213iCA2-1123223 1760660851 | T17: =LEFT(S17,FIND(" ",S17)-1) -> 2213iCA2-1123223 | U17: =CONCATENATE(0,RIGHT(S17,LEN(S17)-FIND(" ",S17))) -> 0 1760660851 | W17: B21 EAST OF KAILASHNew Delhi - 110065 DELHI New Delhi-INDIA | X17: =SUBSTITUTE(W17,"New Delhi","") -> B21 EAST OF KAILASH - 110065 DELHI -INDIA | AR17: 8080654 | AS17: =FIXED(AR17) -> 8,080,654.00 | BB17: 84743|2213iCA2-1123223|1760660851|2901|ABC Cable Network(701001)|320|Satellite Channels P. Ltd(DEL701)
A18: 2213ICA2-1124419 | B18: {=VLOOKUP(A18,'Active List'!C:I,{6,7},0)} -> Macwell Marketing Co Pvt Ltd (South Delhi Comm) | C18: 1 | K18: 2213ICA2-1124419 | L18: =INDEX('Active List'!A:A,MATCH(Sheet1!K18,'Active List'!C:C,0)) -> 84992 | S18: 2213ICA2-1124419 1760348286 | T18: =LEFT(S18,FIND(" ",S18)-1) -> 2213ICA2-1124419 | U18: =CONCATENATE(0,RIGHT(S18,LEN(S18)-FIND(" ",S18))) -> 0 1760348286 | W18: QTR NO-26,DP JNUNew Delhi - 110067 DELHI New Delhi(INDIA) | X18: =SUBSTITUTE(W18,"New Delhi","") -> QTR NO-26,DP JNU - 110067 DELHI (INDIA) | AR18: 8472454 | AS18: =FIXED(AR18) -> 8,472,454.00 | BB18: 84992|2213ICA2-1124419|1760348286|2869|Indu Vision(700002)|325|Macwell Marketing Co Pvt Ltd (South Delhi Comm)
A19: 06J8BAR49SM34572 | B19: {=VLOOKUP(A19,'Active List'!C:I,{6,7},0)} -> Satellite Channels P. Ltd(DEL701) | C19: 1 | K19: 06J8BAR49SM34572 | L19: =INDEX('Active List'!A:A,MATCH(Sheet1!K19,'Active List'!C:C,0)) -> 85098 | S19: 06J8BAR49SM34572 1760015213 | T19: =LEFT(S19,FIND(" ",S19)-1) -> 06J8BAR49SM34572 | U19: =CONCATENATE(0,RIGHT(S19,LEN(S19)-FIND(" ",S19))) -> 0 1760015213 | W19: B16 2ND FLOOR EAST OF KAILASH | X19: =SUBSTITUTE(W19,"New Delhi","") -> B16 2ND FLOOR EAST OF KAILASH | AR19: 8863594 | AS19: =FIXED(AR19) -> 8,863,594.00 | BB19: 85098|06J8BAR49SM34572|1760015213|2926|WORLD VISION(701026)|320|Satellite Channels P. Ltd(DEL701)
A20: 0707BAU02SM15383 | B20: {=VLOOKUP(A20,'Active List'!C:I,{6,7},0)} -> Satellite Channels P. Ltd(DEL701) | C20: 2 | K20: 0707BAU02SM15383 | L20: =INDEX('Active List'!A:A,MATCH(Sheet1!K20,'Active List'!C:C,0)) -> 85149 | S20: 0707BAU02SM15383 1760192281 | T20: =LEFT(S20,FIND(" ",S20)-1) -> 0707BAU02SM15383 | U20: =CONCATENATE(0,RIGHT(S20,LEN(S20)-FIND(" ",S20))) -> 0 1760192281 | W20: E107 SF Lajpat Nagar | X20: =SUBSTITUTE(W20,"New Delhi","") -> E107 SF Lajpat Nagar | BB20: 85149|0707BAU02SM15383|1760192281|4757|Satellite Channels P Ltd|320|Satellite Channels P. Ltd(DEL701)
A21: 2213ICA2-1000055 | B21: {=VLOOKUP(A21,'Active List'!C:I,{6,7},0)} -> Satellite Channels P. Ltd(DEL701) | C21: 1 | K21: 2213ICA2-1000055 | L21: =INDEX('Active List'!A:A,MATCH(Sheet1!K21,'Active List'!C:C,0)) -> 85151 | S21: 2213ICA2-1000055 1760669008 | T21: =LEFT(S21,FIND(" ",S21)-1) -> 2213ICA2-1000055 | U21: =CONCATENATE(0,RIGHT(S21,LEN(S21)-FIND(" ",S21))) -> 0 1760669008 | W21: I35SECOND FLOOR LAJPAT NAGERI | X21: =SUBSTITUTE(W21,"New Delhi","") -> I35SECOND FLOOR LAJPAT NAGERI | BB21: 85151|2213ICA2-1000055|1760669008|4757|Satellite Channels P Ltd|320|Satellite Channels P. Ltd(DEL701)
A22: 06J8BAR49SM35356 | B22: {=VLOOKUP(A22,'Active List'!C:I,{6,7},0)} -> Satellite Channels P. Ltd(DEL701) | C22: 2 | K22: 06J8BAR49SM35356 | L22: =INDEX('Active List'!A:A,MATCH(Sheet1!K22,'Active List'!C:C,0)) -> 85152 | S22: 06J8BAR49SM35356 1760229817 | T22: =LEFT(S22,FIND(" ",S22)-1) -> 06J8BAR49SM35356 | U22: =CONCATENATE(0,RIGHT(S22,LEN(S22)-FIND(" ",S22))) -> 0 1760229817 | W22: I35SECOND FLOOR | X22: =SUBSTITUTE(W22,"New Delhi","") -> I35SECOND FLOOR | BB22: 85152|06J8BAR49SM35356|1760229817|4757|Satellite Channels P Ltd|320|Satellite Channels P. Ltd(DEL701)
A23: 0708BAU03SM31084 | B23: {=VLOOKUP(A23,'Active List'!C:I,{6,7},0)} -> M D Cable(DEL711) | C23: 1 | K23: 0708BAU03SM31084 | L23: =INDEX('Active List'!A:A,MATCH(Sheet1!K23,'Active List'!C:C,0)) -> 85153 | S23: 0708BAU03SM31084 1760404711 | T23: =LEFT(S23,FIND(" ",S23)-1) -> 0708BAU03SM31084 | U23: =CONCATENATE(0,RIGHT(S23,LEN(S23)-FIND(" ",S23))) -> 0 1760404711 | W23: 1493 LAXMI BAI NAGARNew Delhi - 110044 DELHI New Delhi(INDIA) | X23: =SUBSTITUTE(W23,"New Delhi","") -> 1493 LAXMI BAI NAGAR - 110044 DELHI (INDIA) | BB23: 85153|0708BAU03SM31084|1760404711|3159|M D Cable(711001)|330|M D Cable(DEL711)
A24: 06J8BAR49SM34657 | B24: {=VLOOKUP(A24,'Active List'!C:I,{6,7},0)} -> M D Cable(DEL711) | C24: 2 | K24: 06J8BAR49SM34657 | L24: =INDEX('Active List'!A:A,MATCH(Sheet1!K24,'Active List'!C:C,0)) -> 85154 | S24: 06J8BAR49SM34657 1760128542 | T24: =LEFT(S24,FIND(" ",S24)-1) -> 06J8BAR49SM34657 | U24: =CONCATENATE(0,RIGHT(S24,LEN(S24)-FIND(" ",S24))) -> 0 1760128542 | W24: 249 Laxmi Bai NagarNew Delhi - 110023 DELHI New Delhi-INDIA | X24: =SUBSTITUTE(W24,"New Delhi","") -> 249 Laxmi Bai Nagar - 110023 DELHI -INDIA | BB24: 85154|06J8BAR49SM34657|1760128542|3159|M D Cable(711001)|330|M D Cable(DEL711)
A25: 2213ICA2-1110436 | B25: {=VLOOKUP(A25,'Active List'!C:I,{6,7},0)} -> M D Cable(DEL711) | C25: 2 | K25: 2213ICA2-1110436 | L25: =INDEX('Active List'!A:A,MATCH(Sheet1!K25,'Active List'!C:C,0)) -> 85156 | S25: 2213ICA2-1110436 1760650606 | T25: =LEFT(S25,FIND(" ",S25)-1) -> 2213ICA2-1110436 | U25: =CONCATENATE(0,RIGHT(S25,LEN(S25)-FIND(" ",S25))) -> 0 1760650606 | W25: 1515LAXMIBAI NAGARNew DelhiNew Delhi - 110044 DELHI New Delhi-INDIA | X25: =SUBSTITUTE(W25,"New Delhi","") -> 1515LAXMIBAI NAGAR - 110044 DELHI -INDIA | BB25: 85156|2213ICA2-1110436|1760650606|3159|M D Cable(711001)|330|M D Cable(DEL711)
A26: 0718BAU02DS17420 | B26: {=VLOOKUP(A26,'Active List'!C:I,{6,7},0)} -> Satellite Channels P. Ltd(DEL701) | C26: 1 | K26: 0718BAU02DS17420 | L26: =INDEX('Active List'!A:A,MATCH(Sheet1!K26,'Active List'!C:C,0)) -> 85157 | S26: 0718BAU02DS17420 1760048507 | T26: =LEFT(S26,FIND(" ",S26)-1) -> 0718BAU02DS17420 | U26: =CONCATENATE(0,RIGHT(S26,LEN(S26)-FIND(" ",S26))) -> 0 1760048507 | W26: A33 IST FLOOR LAJPAT NAGAR I | X26: =SUBSTITUTE(W26,"New Delhi","") -> A33 IST FLOOR LAJPAT NAGAR I | BB26: 85157|0718BAU02DS17420|1760048507|4757|Satellite Channels P Ltd|320|Satellite Channels P. Ltd(DEL701)
A27: 2213ICA2-1001730 | B27: {=VLOOKUP(A27,'Active List'!C:I,{6,7},0)} -> Satellite Channels P. Ltd(DEL701) | C27: 1 | K27: 2213ICA2-1001730 | L27: =INDEX('Active List'!A:A,MATCH(Sheet1!K27,'Active List'!C:C,0)) -> 85158 | S27: 2213ICA2-1001730 1760136613 | T27: =LEFT(S27,FIND(" ",S27)-1) -> 2213ICA2-1001730 | U27: =CONCATENATE(0,RIGHT(S27,LEN(S27)-FIND(" ",S27))) -> 0 1760136613 | W27: 2B13 2ND FLR LAJPAT NAGAR1 | X27: =SUBSTITUTE(W27,"New Delhi","") -> 2B13 2ND FLR LAJPAT NAGAR1 | BB27: 85158|2213ICA2-1001730|1760136613|4757|Satellite Channels P Ltd|320|Satellite Channels P. Ltd(DEL701)
A28: 06J8BAR49SM34669 | B28: {=VLOOKUP(A28,'Active List'!C:I,{6,7},0)} -> Satellite Channels P. Ltd(DEL701) | C28: 1 | K28: 06J8BAR49SM34669 | L28: =INDEX('Active List'!A:A,MATCH(Sheet1!K28,'Active List'!C:C,0)) -> 85161 | S28: 06J8BAR49SM34669 1760127674 | T28: =LEFT(S28,FIND(" ",S28)-1) -> 06J8BAR49SM34669 | U28: =CONCATENATE(0,RIGHT(S28,LEN(S28)-FIND(" ",S28))) -> 0 1760127674 | W28: A6 3RD FLOOR EAST OF KAILASH | X28: =SUBSTITUTE(W28,"New Delhi","") -> A6 3RD FLOOR EAST OF KAILASH | BB28: 85161|06J8BAR49SM34669|1760127674|2926|WORLD VISION(701026)|320|Satellite Channels P. Ltd(DEL701)
A29: 06J8BAR49SM34670 | B29: {=VLOOKUP(A29,'Active List'!C:I,{6,7},0)} -> Satellite Channels P. Ltd(DEL701) | C29: 1 | K29: 06J8BAR49SM34670 | L29: =INDEX('Active List'!A:A,MATCH(Sheet1!K29,'Active List'!C:C,0)) -> 85162 | S29: 06J8BAR49SM34670 1760127675 | T29: =LEFT(S29,FIND(" ",S29)-1) -> 06J8BAR49SM34670 | U29: =CONCATENATE(0,RIGHT(S29,LEN(S29)-FIND(" ",S29))) -> 0 1760127675 | W29: G39A G/F BACKSIDE EAST OF KAIALSH | X29: =SUBSTITUTE(W29,"New Delhi","") -> G39A G/F BACKSIDE EAST OF KAIALSH | BB29: 85162|06J8BAR49SM34670|1760127675|2926|WORLD VISION(701026)|320|Satellite Channels P. Ltd(DEL701)
A30: 06J8BAR49SM34672 | B30: {=VLOOKUP(A30,'Active List'!C:I,{6,7},0)} -> Satellite Channels P. Ltd(DEL701) | C30: 2 | K30: 06J8BAR49SM34672 | L30: =INDEX('Active List'!A:A,MATCH(Sheet1!K30,'Active List'!C:C,0)) -> 85163 | S30: 06J8BAR49SM34672 1760386185 | T30: =LEFT(S30,FIND(" ",S30)-1) -> 06J8BAR49SM34672 | U30: =CONCATENATE(0,RIGHT(S30,LEN(S30)-FIND(" ",S30))) -> 0 1760386185 | W30: B162 EAST OK KAILASH | X30: =SUBSTITUTE(W30,"New Delhi","") -> B162 EAST OK KAILASH | BB30: 85163|06J8BAR49SM34672|1760386185|2901|ABC Cable Network(701001)|320|Satellite Channels P. Ltd(DEL701)
A31: 06J8BAR49SM13392 | B31: {=VLOOKUP(A31,'Active List'!C:I,{6,7},0)} -> Macwell Marketing Co Pvt Ltd (South Delhi Comm) | C31: 1 | K31: 06J8BAR49SM13392 | L31: =INDEX('Active List'!A:A,MATCH(Sheet1!K31,'Active List'!C:C,0)) -> 85165 | S31: 06J8BAR49SM13392 1760484650 | T31: =LEFT(S31,FIND(" ",S31)-1) -> 06J8BAR49SM13392 | U31: =CONCATENATE(0,RIGHT(S31,LEN(S31)-FIND(" ",S31))) -> 0 1760484650 | W31: QTR NO- 140, UTTARAKHAND(SR)JNUNew Delhi - 110067 DELHI New Delhi(INDIA) | X31: =SUBSTITUTE(W31,"New Delhi","") -> QTR NO- 140, UTTARAKHAND(SR)JNU - 110067 DELHI (INDIA) | BB31: 85165|06J8BAR49SM13392|1760484650|2869|Indu Vision(700002)|325|Macwell Marketing Co Pvt Ltd (South Delhi Comm)
... A46: 06J8BAR49SM29743 | B46: {=VLOOKUP(A46,'Active List'!C:I,{6,7},0)} -> Satellite Channels P. Ltd(DEL701) | C46: 1 | K46: 06J8BAR49SM29743 | L46: =INDEX('Active List'!A:A,MATCH(Sheet1!K46,'Active List'!C:C,0)) -> 85194 | S46: 06J8BAR49SM29743 1760650746 | T46: =LEFT(S46,FIND(" ",S46)-1) -> 06J8BAR49SM29743 | U46: =CONCATENATE(0,RIGHT(S46,LEN(S46)-FIND(" ",S46))) -> 0 1760650746 | W46: 2/8B JUNGPURA | X46: =SUBSTITUTE(W46,"New Delhi","") -> 2/8B JUNGPURA | BB46: 85194|06J8BAR49SM29743|1760650746|2914|CHHABRA CABLE TV NETWORK(701014)|320|Satellite Channels P. Ltd(DEL701)

Sheet Active List
A1: SMSID | B1: Name | C1: STB | D1: VC | E1: LCO_Code | F1: LCO_Name | G1: Distributor_Code | H1: Distributor_Name | I1: Status | J1: LastdeREdate | K1: MobileNumber | L1: SAF_Number | M1: Address | N1: Phase
A2: 83222 | B2: BHAGAT DARSHAN SINGH | C2: 06H9BAR42LT00028 | D2: 1760105267 | E2: 3159 | F2: M D Cable(711001) | G2: 330 | H2: M D Cable(DEL711) | I2: 1 | J2: ' | K2: 9868170779 | L2: 1282922 | M2: 476, TYPEIV LAXMI BAI NAGARNEW DELHI - 110023 DELHI NEW DELHI(INDIA) | N2: 1
A3: 83340 | B3: Sat Pal | C3: 06H9BAR42LT00200 | D3: 1760347043 | E3: 3146 | F3: Om Shree Balalji Media Communication(708017) | G3: 325 | H3: Macwell Marketing Co Pvt Ltd (South Delhi Comm) | I3: 1 | J3: ' | K3: 9910491120 | L3: 161438 | M3: 96/FF HUMAYUN PUR,NEW DELHI - 110029 DELHI NEW DELHI(INDIA) | N3: 1
A4: 83540 | B4: PRASHANT | C4: 2213ICA2-1036259 | D4: 1760420917 | E4: 3155 | F4: Classic Vision(710002) | G4: 324 | H4: S.K Cable Network(DEL705) | I4: 1 | J4: ' | K4: 9911100112 | L4: 79526 | M4: J4/71 GFLS KHIRKI EXTNNEW DELHI - 110017 DELHI NEW DELHI(INDIA) | N4: 1
A5: 83541 | B5: SGT SP Yadav | C5: 06J8BAR49SM11680 | D5: 1760465717 | E5: 2887 | F5: Air Force Cable TV Network(700017) | G5: 325 | H5: Macwell Marketing Co Pvt Ltd (South Delhi Comm) | I5: 1 | J5: ' | K5: 9968360716 | L5: 158936 | M5: 19 C/1 NWC, AIR FORCE STATION RACE COURSENEW DELHINEW DELHI - 110003 DELHI NEW DELHI(INDIA) | N5: 1
A6: 83764 | B6: AKHILESH MISHRA | C6: 06J8BAR49SM32573 | D6: 1760344903 | E6: 3149 | F6: Mini Cable Darshan(709002) | G6: 324 | H6: S.K Cable Network(DEL705) | I6: 2 | J6: '05/05/2013 | L6: 170109 | M6: H16/271 SANGAM VIHAR
A7: 83811 | B7: G. S. BAIDI | C7: 06J8BAR49SM32647 | D7: 1760347846 | E7: 4757 | F7: Satellite Channels P Ltd | G7: 320 | H7: Satellite Channels P. Ltd(DEL701) | I7: 1 | J7: ' | K7: 1129816876 | L7: 97419 | M7: L 31 S FLR LAJPAT NGR II | N7: 1
A8: 84077 | B8: SANJAY KUMAR | C8: 0718BAU02DS10867 | D8: 1760447627 | E8: 2876 | F8: Citi Communication(700006) | G8: 325 | H8: Macwell Marketing Co Pvt Ltd (South Delhi Comm) | I8: 2 | J8: '07/03/2013 | K8: 9810499577 | L8: 174778 | M8: H.N0.3 F.F.ARJUN NGR.NEW DELHI - 110016 DELHI NEW DELHI-INDIA
A9: 84131 | B9: RAGHVENDRA | C9: 2213ICA2-1033156 | D9: 1761333827 | E9: 4300 | F9: Sky Net Cable Network(705029) | G9: 324 | H9: S.K Cable Network(DEL705) | I9: 1 | J9: ' | K9: 9582149249 | L9: 84131 | M9: FLAT NO. 96/5 SEC-1 PUSHP VIHAR | N9: 1
A10: 84259 | B10: SUDARSHAN SACHDEV | C10: 06j8bar49sm27232 | D10: 1760134838 | E10: 2933 | F10: Channi Cable Waves(701033) | G10: 320 | H10: Satellite Channels P. Ltd(DEL701) | I10: 1 | J10: ' | K10: 9311681419 | L10: 34941 | M10: 3/1 IIIRD FLOOR JANGPURA EXTNNEW DELHI - 110014 DELHI NEW DELHI(INDIA) | N10: 1
A11: 84389 | B11: M P SETHY | C11: 0773BAU27DS27547 | D11: 1760203666 | E11: 3159 | F11: M D Cable(711001) | G11: 330 | H11: M D Cable(DEL711) | I11: 1 | J11: ' | K11: 9958773564 | L11: 1282923 | M11: DII/52 WEST KIDWAI NAGARNEW DELHI - 110023 DELHI NEW DELHI(INDIA) | N11: 1
A12: 84390 | B12: DEVENDRA KUMAR | C12: 2213ICA2-1033581 | D12: 1760597792 | E12: 3159 | F12: M D Cable(711001) | G12: 330 | H12: M D Cable(DEL711) | I12: 1 | J12: ' | K12: 9953751732 | L12: 1282924 | M12: C3 TYPEIII WEST KIDWAI NAGARNEW DELHI - 110023 DELHI NEW DELHI(INDIA) | N12: 1
A13: 84392 | B13: PADMA VATI | C13: 06J8BAR49SM33494 | D13: 1760344576 | E13: 3159 | F13: M D Cable(711001) | G13: 330 | H13: M D Cable(DEL711) | I13: 1 | J13: ' | K13: 9871242672 | L13: 1282925 | M13: 288,LAXMI BAI NAGARNEW DELHI - 110023 DELHI NEW DELHI(INDIA) | N13: 1
A14: 84393 | B14: D PRASAD | C14: 0708BAU03SM31087 | D14: 1760421982 | E14: 3159 | F14: M D Cable(711001) | G14: 330 | H14: M D Cable(DEL711) | I14: 1 | J14: ' | K14: 9868264453 | L14: 1282926 | M14: 345LAXMI BAI NAGARNEW DELHI - 110023 DELHI NEW DELHI(INDIA) | N14: 1
A15: 84721 | B15: AJIT SINGH | C15: 2213ICA2-1022226 | D15: 1760570248 | E15: 2924 | F15: SIMRAN ENTERPRISES(701024) | G15: 320 | H15: Satellite Channels P. Ltd(DEL701) | I15: 1 | J15: ' | K15: 9971950672 | L15: 125023 | M15: Q20BIST FLOOR | N15: 1
A16: 84743 | B16: VIKAS | C16: 2213iCA2-1123223 | D16: 1760660851 | E16: 2901 | F16: ABC Cable Network(701001) | G16: 320 | H16: Satellite Channels P. Ltd(DEL701) | I16: 2 | J16: '19/02/2013 | K16: 9810163057 | L16: 174216 | M16: B21 EAST OF KAILASHNEW DELHI - 110065 DELHI NEW DELHI-INDIA
A17: 84992 | B17: D.S.Rawat | C17: 2213ICA2-1124419 | D17: 1760348286 | E17: 2869 | F17: Indu Vision(700002) | G17: 325 | H17: Macwell Marketing Co Pvt Ltd (South Delhi Comm) | I17: 1 | J17: ' | K17: 9211248978 | L17: 734217 | M17: QTR NO-26,DP JNUNEW DELHI - 110067 DELHI NEW DELHI(INDIA) | N17: 1
A18: 85098 | B18: SURAJIT DUTTA | C18: 06J8BAR49SM34572 | D18: 1760015213 | E18: 2926 | F18: WORLD VISION(701026) | G18: 320 | H18: Satellite Channels P. Ltd(DEL701) | I18: 1 | J18: ' | K18: 9810006996 | L18: 10412 | M18: B16 2ND FLOOR EAST OF KAILASH | N18: 1
A19: 85149 | B19: ANIL SHREENIVASAN | C19: 0707BAU02SM15383 | D19: 1760192281 | E19: 4757 | F19: Satellite Channels P Ltd | G19: 320 | H19: Satellite Channels P. Ltd(DEL701) | I19: 2 | J19: '29/03/2011 | K19: 9818434760 | L19: 111102 | M19: E107 SF Lajpat Nagar
A20: 85151 | B20: KAPIL SADH | C20: 2213ICA2-1000055 | D20: 1760669008 | E20: 4757 | F20: Satellite Channels P Ltd | G20: 320 | H20: Satellite Channels P. Ltd(DEL701) | I20: 1 | J20: ' | K20: 9350005308 | L20: 104015 | M20: I35SECOND FLOOR LAJPAT NAGERI | N20: 1
A21: 85152 | B21: KAPIL SADH | C21: 06J8BAR49SM35356 | D21: 1760229817 | E21: 4757 | F21: Satellite Channels P Ltd | G21: 320 | H21: Satellite Channels P. Ltd(DEL701) | I21: 2 | J21: '04/04/2013 | K21: 9350005308 | L21: 104014 | M21: I35SECOND FLOOR
A22: 85153 | B22: RAJESH KUMAR | C22: 0708BAU03SM31084 | D22: 1760404711 | E22: 3159 | F22: M D Cable(711001) | G22: 330 | H22: M D Cable(DEL711) | I22: 1 | J22: ' | K22: 9871368378 | L22: 1282927 | M22: 1493 LAXMI BAI NAGARNEW DELHI - 110044 DELHI NEW DELHI(INDIA) | N22: 1
A23: 85154 | B23: VIJAY SHARAN MATHUR | C23: 06J8BAR49SM34657 | D23: 1760128542 | E23: 3159 | F23: M D Cable(711001) | G23: 330 | H23: M D Cable(DEL711) | I23: 2 | J23: '02/05/2013 | K23: 9999999999 | L23: 21320 | M23: 249 Laxmi Bai NagarNEW DELHI - 110023 DELHI NEW DELHI-INDIA
A24: 85156 | B24: ASHOK KUMAR SINGH | C24: 2213ICA2-1110436 | D24: 1760650606 | E24: 3159 | F24: M D Cable(711001) | G24: 330 | H24: M D Cable(DEL711) | I24: 2 | J24: '26/08/2013 | K24: 1126874210 | L24: 1282928 | M24: 1515LAXMIBAI NAGARNEW DELHINEW DELHI - 110044 DELHI NEW DELHI-INDIA
A25: 85157 | B25: ANJU GERA | C25: 0718BAU02DS17420 | D25: 1760048507 | E25: 4757 | F25: Satellite Channels P Ltd | G25: 320 | H25: Satellite Channels P. Ltd(DEL701) | I25: 1 | J25: ' | K25: 298166616 | L25: 98513 | M25: A33 IST FLOOR LAJPAT NAGAR I | N25: 1
A26: 85158 | B26: SANJAY | C26: 2213ICA2-1001730 | D26: 1760136613 | E26: 4757 | F26: Satellite Channels P Ltd | G26: 320 | H26: Satellite Channels P. Ltd(DEL701) | I26: 1 | J26: ' | K26: 9312107920 | L26: 97915 | M26: 2B13 2ND FLR LAJPAT NAGAR1 | N26: 1
A27: 85161 | B27: SHARMALA KUMAR | C27: 06J8BAR49SM34669 | D27: 1760127674 | E27: 2926 | F27: WORLD VISION(701026) | G27: 320 | H27: Satellite Channels P. Ltd(DEL701) | I27: 1 | J27: ' | K27: 9910268174 | L27: 20539 | M27: A6 3RD FLOOR EAST OF KAILASH | N27: 1
A28: 85162 | B28: AVINASH CHANDER CHAWLA | C28: 06J8BAR49SM34670 | D28: 1760127675 | E28: 2926 | F28: WORLD VISION(701026) | G28: 320 | H28: Satellite Channels P. Ltd(DEL701) | I28: 1 | J28: ' | K28: 9312275965 | L28: 35036 | M28: G39A G/F BACKSIDE EAST OF KAIALSH | N28: 1
A29: 85163 | B29: DR.HARGYAN SINGH | C29: 06J8BAR49SM34672 | D29: 1760386185 | E29: 2901 | F29: ABC Cable Network(701001) | G29: 320 | H29: Satellite Channels P. Ltd(DEL701) | I29: 2 | J29: '22/12/2012 | L29: 172123 | M29: B162 EAST OK KAILASH
A30: 85165 | B30: RAGHUVEER SINGH | C30: 06J8BAR49SM13392 | D30: 1760484650 | E30: 2869 | F30: Indu Vision(700002) | G30: 325 | H30: Macwell Marketing Co Pvt Ltd (South Delhi Comm) | I30: 1 | J30: ' | K30: 9211248978 | L30: 734293 | M30: QTR NO- 140, UTTARAKHAND(SR)JNUNEW DELHI - 110067 DELHI NEW DELHI(INDIA) | N30: 1
A31: 85166 | B31: JNAIS | C31: 06J8BAR49SM34675 | D31: 1760127445 | E31: 2869 | F31: Indu Vision(700002) | G31: 325 | H31: Macwell Marketing Co Pvt Ltd (South Delhi Comm) | I31: 2 | J31: '03/10/2013 | K31: 9211248978 | L31: 734535 | M31: ROOM NO 106JNUNEW DELHI
A32: 85167 | B32: IMC | C32: 06J8BAR49SM34681 | D32: 1760132276 | E32: 2869 | F32: Indu Vision(700002) | G32: 325 | H32: Macwell Marketing Co Pvt Ltd (South Delhi Comm) | I32: 1 | J32: ' | K32: 9211248978 | L32: 734517 | M32: Recreation Room IISJNUNEW DELHI - 110067 DELHI NEW DELHI(INDIA) | N32: 1
A33: 85171 | B33: SHRI CHAND | C33: 2213ICA2-1110668 | D33: 1760347266 | E33: 2986 | F33: A V Cable Network (Badarpur)(702030) | G33: 321 | H33: S.S Communications(DEL702) | I33: 2 | J33: '17/01/2013 | L33: 169305 | M33: C197 PAL PRALADPUR
A34: 85172 | B34: MAANAS | C34: 06J8BAR49SM34693 | D34: 1760128608 | E34: 2905 | F34: Vicky Cable TV(701005) | G34: 320 | H34: Satellite Channels P. Ltd(DEL701) | I34: 1 | J34: ' | K34: 9899407919 | L34: 162826 | M34: 39F GALI No5 APB GARHI NEW DELHINEW DELHI - 110065 DELHI NEW DELHI(INDIA) | N34: 1
A35: 85174 | B35: BHAGWAN DAS | C35: 06J8BAR49SM17483 | D35: 1760142477 | E35: 2876 | F35: Citi Communication(700006) | G35: 325 | H35: Macwell Marketing Co Pvt Ltd (South Delhi Comm) | I35: 1 | J35: ' | K35: 9999775518 | L35: 1555865 | M35: 26,1,st.FLOOR,ARJUN NAGARNEW-DELHINEW DELHI - 110029 DELHI NEW DELHI(INDIA) | N35: 1
A36: 85175 | B36: MAHAK ARORA | C36: 2213ICA2-1004949 | D36: 1740013626 | E36: 2876 | F36: Citi Communication(700006) | G36: 325 | H36: Macwell Marketing Co Pvt Ltd (South Delhi Comm) | I36: 2 | J36: '26/02/2013 | K36: 9899840810 | L36: 44481 | M36: 39 GROUND FLOORARJUN NAGAR
A37: 85176 | B37: SURESH RAMANI | C37: 06J8BAR49SM34703 | D37: 1760127503 | E37: 2944 | F37: Tele Video Cable Vision(701044) | G37: 320 | H37: Satellite Channels P. Ltd(DEL701) | I37: 2 | J37: '02/09/2013 | K37: 9810058123 | L37: 59752 | M37: 4/27GF NEHRU NAGARNEW DELHI - 110065 DELHI NEW DELHI-INDIA
A38: 85177 | B38: KRAISHAN | C38: 2213ICA2-1122828 | D38: 1760228184 | E38: 2944 | F38: Tele Video Cable Vision(701044) | G38: 320 | H38: Satellite Channels P. Ltd(DEL701) | I38: 1 | J38: ' | K38: 9810869255 | L38: 59394 | M38: S70/80 JAL VIHAR | N38: 1
A39: 85179 | B39: Mrs.Ruchi | C39: 06J8BAR49SM27718 | D39: 1760483879 | E39: 2873 | F39: Rukku Cable Network(700004) | G39: 325 | H39: Macwell Marketing Co Pvt Ltd (South Delhi Comm) | I39: 1 | J39: ' | K39: 1126565419 | L39: 1026895 | M39: E37FFHAUZ KHASNew Delhi | N39: 1
A40: 85180 | B40: BALVINDER SINGH RANDHA | C40: 2213ICA2-1061769 | D40: 1760220707 | E40: 2889 | F40: Verma Cable Vision(700019) | G40: 325 | H40: Macwell Marketing Co Pvt Ltd (South Delhi Comm) | I40: 1 | J40: ' | K40: 9810296913 | L40: 1571061 | M40: 12/227 LODHI COLONYnew delhi | N40: 1
...

Sheet Sheet2
